#VRML_SIM R2023b utf8

EXTERNPROTO "https://raw.githubusercontent.com/cyberbotics/webots/R2023a/projects/objects/floors/protos/CircleArena.proto"

WorldInfo {
  ERP 0.8
  basicTimeStep 2
  dragForceScale 1000
  contactProperties [
    ContactProperties {
    }
  ]
}
Viewpoint {
  orientation 0.15758130468039516 0.49088993159360494 -0.856851916888356 0.7169110161604323
  position -2.592654238101432 2.0014537728217987 1.6664170021765219
}
TexturedBackground {
}
TexturedBackgroundLight {
}
CircleArena {
  radius 100
  floorTileSize 2 2
}
Robot {
  name "Ros2Supervisor"
  controller "<extern>"
  supervisor TRUE
}
Robot {
  translation 0 0 0.5
  children [
    Accelerometer {
    }
    InertialUnit {
      name "imu"
    }
    Gyro {
    }
    GPS {
    }
    Shape {
      appearance DEF base_link_material PBRAppearance {
        baseColor 0.69804 0.69804 0.69804
        roughness 1
        metalness 0
      }
      geometry DEF base_link Mesh {
        url [
          "/usr/share/robot_description/bikeR/meshes/base_link.STL"
        ]
      }
    }
    HingeJoint {
      jointParameters HingeJointParameters {
        axis 0.309018 0 -0.951056
        anchor 0.36825 0 -0.003122
      }
      device [
        RotationalMotor {
          name "joint_front_turn"
          maxVelocity 12.5
          minPosition -1.3
          maxPosition 1.3
          maxTorque 20
        }
        PositionSensor {
          name "joint_front_turn_sensor"
        }
      ]
      endPoint Solid {
        translation 0.36825 0 -0.003122
        rotation 0 -1 0 0.31416
        children [
          Shape {
            appearance DEF front_turn_material PBRAppearance {
              baseColor 0.69804 0.69804 0.69804
              roughness 1
              metalness 0
            }
            geometry DEF front_turn Mesh {
              url [
                "/usr/share/robot_description/bikeR/meshes/front_turn.STL"
              ]
            }
          }
          HingeJoint {
            jointParameters HingeJointParameters {
              axis 1e-06 1 3e-06
              anchor 0 0 -0.32635
            }
            device [
              RotationalMotor {
                name "joint_f_wheel"
                maxVelocity 200
                minPosition -10000
                maxPosition 10000
                maxTorque 30
              }
              PositionSensor {
                name "joint_f_wheel_sensor"
              }
            ]
            endPoint Solid {
              translation 0 0 -0.32635
              rotation 0.9758204057218136 0.1545550642601452 -0.1545550642601452 1.595274
              children [
                Shape {
                  appearance DEF front_wheel_material PBRAppearance {
                    baseColor 0.69804 0.69804 0.69804
                    roughness 1
                    metalness 0
                  }
                  geometry DEF front_wheel Mesh {
                    url [
                      "/usr/share/robot_description/bikeR/meshes/front_wheel.STL"
                    ]
                  }
                }
              ]
              name "front_wheel"
              boundingObject USE front_wheel
              physics Physics {
                density -1
                mass 3.588928
                centerOfMass [
                  4e-06 1.3e-05 0.00054
                ]
                inertiaMatrix [
                  0.03120089 0.03119983 0.06130831
                  -3.7e-07 3.8e-07 5.3e-07
                ]
              }
            }
          }
        ]
        name "front_turn"
        boundingObject USE front_turn
        physics Physics {
          density -1
          mass 0.517747
          centerOfMass [
            0 0 -0.090357
          ]
          inertiaMatrix [
            0.00872423 0.00809841 0.00067395
            0 0 0
          ]
        }
      }
    }
    HingeJoint {
      jointParameters HingeJointParameters {
        axis 0 1 4e-06
        anchor -0.1709 0 -0.3135
      }
      device [
        RotationalMotor {
          name "joint_rear_wheel"
          maxVelocity 200
          minPosition -1000000
          maxPosition 10000000
          maxTorque 30
        }
        PositionSensor {
          name "joint_rear_wheel_sensor"
        }
      ]
      endPoint Solid {
        translation -0.1709 0 -0.3135
        rotation 1 0 0 1.5708
        children [
          Shape {
            appearance DEF rear_wheel_material PBRAppearance {
              baseColor 0.69804 0.69804 0.69804
              roughness 1
              metalness 0
            }
            geometry DEF rear_wheel Mesh {
              url [
                "/usr/share/robot_description/bikeR/meshes/rear_wheel.STL"
              ]
            }
          }
        ]
        name "rear_wheel"
        boundingObject USE rear_wheel
        physics Physics {
          density -1
          mass 3.588928
          centerOfMass [
            -1e-05 1e-05 0.00054
          ]
          inertiaMatrix [
            0.03120036 0.03120036 0.06130831
            6.5e-07 -3e-07 5.9e-07
          ]
        }
      }
    }
  ]
  name "bikeR_webots"
  boundingObject USE base_link
  
  controller "<extern>"
}
Solid {
  translation -0.1 0.13 0.15
  children [
    DEF b Shape {
      appearance PBRAppearance {
      }
      geometry Box {
        size 0.4 0.1 0.3
      }
    }
  ]
  boundingObject USE b
}
Solid {
  translation -0.1 -0.13 0.15
  children [
    DEF b Shape {
      appearance PBRAppearance {
      }
      geometry Box {
        size 0.4 0.1 0.3
      }
    }
  ]
  name "solid(1)"
  boundingObject USE b
}
