#VRML_SIM R2023b utf8

EXTERNPROTO "https://raw.githubusercontent.com/cyberbotics/webots/R2023a/projects/objects/floors/protos/CircleArena.proto"

WorldInfo {
  ERP 0.8
  basicTimeStep 2
  dragForceScale 1000
  contactProperties [
    ContactProperties {
    }
  ]
}
Viewpoint {
  orientation 0.14218287192764362 0.23686368494040627 -0.9610825280312087 1.116594565618964
  position -1.363885590517051 2.943559547722536 1.4353041718418185
}
TexturedBackground {
}
TexturedBackgroundLight {
}
CircleArena {
  radius 100
  floorTileSize 2 2
}
Robot {
  name "Ros2Supervisor"
  controller "<extern>"
  supervisor TRUE
}
Robot {
    translation 0 0 0.5
    children [
        Accelerometer {
        }
        InertialUnit {
        name "imu"
        }
        Gyro {
        }
        GPS {
        }
        Shape {
        appearance DEF base_link_material PBRAppearance {
            baseColor 0.698040 0.698040 0.698040
            roughness 1.000000
            metalness 0
        }
        geometry DEF base_link Mesh {
            url "/usr/share/robot_description/bikeR/meshes/base_link.STL"
        }
        }
        HingeJoint {
        jointParameters HingeJointParameters {
            axis 0.309018 0.000000 -0.951056
            anchor 0.368250 0.000000 -0.003122
        }
        device [
            RotationalMotor {
            name "joint_front_turn"
            maxVelocity 12.5
            minPosition -1.3
            maxPosition 1.3
            maxTorque 20.0
            }
            PositionSensor {
            name "joint_front_turn_sensor"
            }
        ]
        endPoint Solid {
            translation 0.368250 0.000000 -0.003122
            rotation 0.000000 -1.000000 0.000000 0.314160
            children [
            Shape {
                appearance DEF front_turn_material PBRAppearance {
                baseColor 0.698040 0.698040 0.698040
                roughness 1.000000
                metalness 0
                }
                geometry DEF front_turn Mesh {
                url "/usr/share/robot_description/bikeR/meshes/front_turn.STL"
                }
            }
            HingeJoint {
                jointParameters HingeJointParameters {
                axis 0.000001 1.000000 0.000003
                anchor 0.000000 0.000000 -0.326350
                }
                device [
                RotationalMotor {
                    name "joint_f_wheel"
                    maxVelocity 200
                    minPosition -10000
                    maxPosition 10000
                    maxTorque 30
                }
                PositionSensor {
                    name "joint_f_wheel_sensor"
                }
                ]
                endPoint Solid {
                translation 0.000000 0.000000 -0.326350
                rotation 0.975820 0.154555 -0.154555 1.595274
                children [
                    Shape {
                    appearance DEF front_wheel_material PBRAppearance {
                        baseColor 0.698040 0.698040 0.698040
                        roughness 1.000000
                        metalness 0
                    }
                    geometry DEF front_wheel Mesh {
                        url "/usr/share/robot_description/bikeR/meshes/front_wheel.STL"
                    }
                    }
                ]
                name "front_wheel"
                boundingObject USE front_wheel
                physics Physics {
                    density -1
                    mass 3.588928
                    centerOfMass [ 0.000004 0.000013 0.000540 ]
                    inertiaMatrix [
                    3.120089e-02 3.119983e-02 6.130831e-02
                    -3.700000e-07 3.800000e-07 5.300000e-07
                    ]
                }
                }
            }
            ]
            name "front_turn"
            boundingObject USE front_turn
            physics Physics {
            density -1
            mass 0.517747
            centerOfMass [ 0.000000 0.000000 -0.090357 ]
            inertiaMatrix [
                8.724230e-03 8.098410e-03 6.739500e-04
                0.000000e+00 0.000000e+00 0.000000e+00
            ]
            }
        }
        }
        HingeJoint {
        jointParameters HingeJointParameters {
            axis 0.000000 1.000000 0.000004
            anchor -0.170900 0.000000 -0.313500
        }
        device [
            RotationalMotor {
            name "joint_rear_wheel"
            maxVelocity 200
            minPosition -1000000
            maxPosition 10000000
            maxTorque 30
            }
            PositionSensor {
            name "joint_rear_wheel_sensor"
            }
        ]
        endPoint Solid {
            translation -0.170900 0.000000 -0.313500
            rotation 1.000000 0.000000 0.000000 1.570800
            children [
            Shape {
                appearance DEF rear_wheel_material PBRAppearance {
                baseColor 0.698040 0.698040 0.698040
                roughness 1.000000
                metalness 0
                }
                geometry DEF rear_wheel Mesh {
                url "/usr/share/robot_description/bikeR/meshes/rear_wheel.STL"
                }
            }
            ]
            name "rear_wheel"
            boundingObject USE rear_wheel
            physics Physics {
            density -1
            mass 3.588928
            centerOfMass [ -0.000010 0.000010 0.000540 ]
            inertiaMatrix [
                3.120036e-02 3.120036e-02 6.130831e-02
                6.500000e-07 -3.000000e-07 5.900000e-07
            ]
            }
        }
        }
    ]
    name "bikeR_webots"
    boundingObject USE base_link
    physics Physics {
        density -1
        mass 5.862919
        centerOfMass [ 0.141573 0.000000 -0.068330 ]
        inertiaMatrix [
        9.498332e-02 1.835896e-01 9.721400e-02
        -3.000000e-08 1.850790e-03 1.000000e-08
        ]
    }
    controller "<extern>"
}