<?xml version="1.0"?>
<robot xmlns:xacro="http://www.ros.org/wiki/xacro" name="bike">
  <xacro:macro name="description">
    <link
      name="base_link">
      <inertial>
        <origin
          xyz="0.058013 1.5196E-06 -0.18889"
          rpy="0 0 0" />
        <mass
          value="8.5884" />
        <inertia
          ixx="0.26235"
          ixy="1.7411E-06"
          ixz="-0.20526"
          iyy="0.75125"
          iyz="1.4708E-06"
          izz="0.50128" />
      </inertial>
      <visual>
        <origin
          xyz="0 0 0"
          rpy="0 0 0" />
        <geometry>
          <mesh
            filename="../meshes/base_link.STL" />
        </geometry>
        <material
          name="">
          <color
            rgba="0.89804 0.91765 0.92941 1" />
        </material>
      </visual>
      <collision>
        <origin
          xyz="0 0 0"
          rpy="0 0 0" />
        <geometry>
          <mesh
            filename="../meshes/base_link.STL" />
        </geometry>
      </collision>
    </link>
    <joint name="imu_joint" type="fixed">
      <parent link="base_link"/>
      <child link="imu_link"/>
      <origin rpy="0 0 0" xyz="0 0 0"/>
    </joint>

    <link name="imu_link">
      <inertial>
        <mass value="0.001"/>
        <origin rpy="0 0 0" xyz="0 0 0"/>
        <inertia ixx="0.0001" ixy="0" ixz="0" iyy="0.0001" iyz="0" izz="0.0001"/>
      </inertial>
      <visual>
        <origin rpy="0 0 0" xyz="0 0 0"/>
        <geometry>
          <box size="0.001 0.001 0.001"/>
        </geometry>
        <material name="red"/>
      </visual>
      <collision>
        <origin rpy="0 0 0" xyz="0 0 0"/>
        <geometry>
          <box size=".001 .001 .001"/>
        </geometry>
      </collision>
    </link>
    <link
      name="front_turn">
      <inertial>
        <origin
          xyz="0.00014354 3.0121E-07 -0.34228"
          rpy="0 0 0" />
        <mass
          value="0.27217" />
        <inertia
          ixx="0.0042191"
          ixy="-1.9762E-11"
          ixz="-6.6991E-06"
          iyy="0.0037097"
          iyz="2.0584E-10"
          izz="0.00054854" />
      </inertial>
      <visual>
        <origin
          xyz="0 0 0"
          rpy="0 0 0" />
        <geometry>
          <mesh
            filename="../meshes/front_turn.STL" />
        </geometry>
        <material
          name="">
          <color
            rgba="0.69804 0.69804 0.69804 1" />
        </material>
      </visual>
      <collision>
        <origin
          xyz="0 0 0"
          rpy="0 0 0" />
        <geometry>
          <mesh
            filename="../meshes/front_turn.STL" />
        </geometry>
      </collision>
    </link>
    <joint
      name="joint_front_turn"
      type="revolute">
      <origin
        xyz="0.46535 0 0.12607"
        rpy="0 -0.34907 0" />
      <parent
        link="base_link" />
      <child
        link="front_turn" />
      <axis
        xyz="0 0 -1" />
      <limit effort="100" lower="-1.3" upper="1.3" velocity="12.5"/>
    </joint>
    <link
      name="front_wheel">
      <inertial>
        <origin
          xyz="-4.1633E-17 1.1102E-16 5.3105E-17"
          rpy="0 0 0" />
        <mass
          value="1.5911" />
        <inertia
          ixx="0.064566"
          ixy="1.5468E-17"
          ixz="1.6623E-17"
          iyy="0.064566"
          iyz="7.5899E-19"
          izz="0.12861" />
      </inertial>
      <visual>
        <origin
          xyz="0 0 0"
          rpy="0 0 0" />
        <geometry>
          <mesh
            filename="../meshes/front_wheel.STL" />
        </geometry>
        <material
          name="">
          <color
            rgba="0.69804 0.69804 0.69804 1" />
        </material>
      </visual>
      <collision>
        <origin
          xyz="0 0 0"
          rpy="0 0 0" />
        <geometry>
          <cylinder length="0.05" radius="0.33"/>
        </geometry>
      </collision>
    </link>
    <joint
      name="joint_f_wheel"
      type="revolute">
      <origin
        xyz="0 0 -0.52791"
        rpy="1.5708 1.2217 3.1416" />
      <parent
        link="front_turn" />
      <child
        link="front_wheel" />
      <axis
        xyz="0 0 1" />
      <limit effort="100" lower="-10000" upper="10000" velocity="200"/>
    </joint>
    <link
      name="rear_wheel">
      <inertial>
        <origin
          xyz="-9.0206E-17 5.5511E-17 3.2298E-18"
          rpy="0 0 0" />
        <mass
          value="1.5911" />
        <inertia
          ixx="0.064566"
          ixy="2.6239E-17"
          ixz="2.3271E-20"
          iyy="0.064566"
          iyz="-1.496E-20"
          izz="0.12861" />
      </inertial>
      <visual>
        <origin
          xyz="0 0 0"
          rpy="0 0 0" />
        <geometry>
          <mesh
            filename="../meshes/rear_wheel.STL" />
        </geometry>
        <material
          name="">
          <color
            rgba="0.69804 0.69804 0.69804 1" />
        </material>
      </visual>
      <collision>
        <origin
          xyz="0 0 0"
          rpy="0 0 0" />
        <geometry>
          <cylinder length="0.05" radius="0.33"/>
        </geometry>
      </collision>
    </link>
    <joint
      name="joint_rear_wheel"
      type="revolute">
      <origin
        xyz="-0.37474 0 -0.37"
        rpy="1.5708 1.5708 0" />
      <parent
        link="base_link" />
      <child
        link="rear_wheel" />
      <axis
        xyz="0 0 -1" />
      <limit effort="100" lower="-1000000" upper="10000000" velocity="200"/>
    </joint>
  </xacro:macro>
</robot>